Failure # 1 (occurred at 2021-02-09_11-21-50)
Traceback (most recent call last):
  File "/home/davidfan/miniconda3/envs/RL/lib/python3.8/site-packages/ray/tune/trial_runner.py", line 519, in _process_trial
    result = self.trial_executor.fetch_result(trial)
  File "/home/davidfan/miniconda3/envs/RL/lib/python3.8/site-packages/ray/tune/ray_trial_executor.py", line 497, in fetch_result
    result = ray.get(trial_future[0], timeout=DEFAULT_GET_TIMEOUT)
  File "/home/davidfan/miniconda3/envs/RL/lib/python3.8/site-packages/ray/worker.py", line 1379, in get
    raise value.as_instanceof_cause()
ray.exceptions.RayTaskError(RuntimeError): [36mray::PPO.train()[39m (pid=2718791, ip=192.168.88.226)
  File "/home/davidfan/miniconda3/envs/RL/lib/python3.8/site-packages/ray/tune/trainable.py", line 183, in train
    result = self.step()
  File "/home/davidfan/miniconda3/envs/RL/lib/python3.8/site-packages/ray/rllib/agents/trainer_template.py", line 147, in step
    res = next(self.train_exec_impl)
  File "/home/davidfan/miniconda3/envs/RL/lib/python3.8/site-packages/ray/util/iter.py", line 756, in __next__
    return next(self.built_iterator)
  File "/home/davidfan/miniconda3/envs/RL/lib/python3.8/site-packages/ray/util/iter.py", line 783, in apply_foreach
    for item in it:
  File "/home/davidfan/miniconda3/envs/RL/lib/python3.8/site-packages/ray/util/iter.py", line 783, in apply_foreach
    for item in it:
  File "/home/davidfan/miniconda3/envs/RL/lib/python3.8/site-packages/ray/util/iter.py", line 843, in apply_filter
    for item in it:
  File "/home/davidfan/miniconda3/envs/RL/lib/python3.8/site-packages/ray/util/iter.py", line 843, in apply_filter
    for item in it:
  File "/home/davidfan/miniconda3/envs/RL/lib/python3.8/site-packages/ray/util/iter.py", line 783, in apply_foreach
    for item in it:
  File "/home/davidfan/miniconda3/envs/RL/lib/python3.8/site-packages/ray/util/iter.py", line 783, in apply_foreach
    for item in it:
  File "/home/davidfan/miniconda3/envs/RL/lib/python3.8/site-packages/ray/util/iter.py", line 783, in apply_foreach
    for item in it:
  [Previous line repeated 1 more time]
  File "/home/davidfan/miniconda3/envs/RL/lib/python3.8/site-packages/ray/util/iter.py", line 876, in apply_flatten
    for item in it:
  File "/home/davidfan/miniconda3/envs/RL/lib/python3.8/site-packages/ray/util/iter.py", line 828, in add_wait_hooks
    item = next(it)
  File "/home/davidfan/miniconda3/envs/RL/lib/python3.8/site-packages/ray/util/iter.py", line 783, in apply_foreach
    for item in it:
  File "/home/davidfan/miniconda3/envs/RL/lib/python3.8/site-packages/ray/util/iter.py", line 783, in apply_foreach
    for item in it:
  File "/home/davidfan/miniconda3/envs/RL/lib/python3.8/site-packages/ray/util/iter.py", line 783, in apply_foreach
    for item in it:
  [Previous line repeated 1 more time]
  File "/home/davidfan/miniconda3/envs/RL/lib/python3.8/site-packages/ray/util/iter.py", line 471, in base_iterator
    yield ray.get(futures, timeout=timeout)
ray.exceptions.RayTaskError(AttributeError): [36mray::RolloutWorker.par_iter_next()[39m (pid=2718789, ip=192.168.88.226)
  File "python/ray/_raylet.pyx", line 463, in ray._raylet.execute_task
  File "python/ray/_raylet.pyx", line 415, in ray._raylet.execute_task.function_executor
  File "/home/davidfan/miniconda3/envs/RL/lib/python3.8/site-packages/ray/util/iter.py", line 1152, in par_iter_next
    return next(self.local_it)
  File "/home/davidfan/miniconda3/envs/RL/lib/python3.8/site-packages/ray/rllib/evaluation/rollout_worker.py", line 323, in gen_rollouts
    yield self.sample()
  File "/home/davidfan/miniconda3/envs/RL/lib/python3.8/site-packages/ray/rllib/evaluation/rollout_worker.py", line 638, in sample
    batches = [self.input_reader.next()]
  File "/home/davidfan/miniconda3/envs/RL/lib/python3.8/site-packages/ray/rllib/evaluation/sampler.py", line 94, in next
    batches = [self.get_data()]
  File "/home/davidfan/miniconda3/envs/RL/lib/python3.8/site-packages/ray/rllib/evaluation/sampler.py", line 211, in get_data
    item = next(self.rollout_provider)
  File "/home/davidfan/miniconda3/envs/RL/lib/python3.8/site-packages/ray/rllib/evaluation/sampler.py", line 651, in _env_runner
    base_env.send_actions(actions_to_send)
  File "/home/davidfan/miniconda3/envs/RL/lib/python3.8/site-packages/ray/rllib/env/base_env.py", line 346, in send_actions
    self.vector_env.vector_step(action_vector)
  File "/home/davidfan/miniconda3/envs/RL/lib/python3.8/site-packages/ray/rllib/env/vector_env.py", line 143, in vector_step
    obs, r, done, info = self.envs[i].step(actions[i])
  File "/home/davidfan/miniconda3/envs/RL/lib/python3.8/site-packages/tensortrade/env/generic/environment.py", line 121, in step
    self.action_scheme.perform(self, action)
  File "/home/davidfan/miniconda3/envs/RL/lib/python3.8/site-packages/tensortrade/env/default/actions.py", line 90, in perform
    orders = self.get_orders(action, self.portfolio)
  File "main_simple.py", line 70, in get_orders
    listener.on_action(action)
AttributeError: 'SimpleProfit' object has no attribute 'on_action'

During handling of the above exception, another exception occurred:

[36mray::PPO.train()[39m (pid=2718791, ip=192.168.88.226)
  File "python/ray/_raylet.pyx", line 456, in ray._raylet.execute_task
  File "python/ray/_raylet.pyx", line 459, in ray._raylet.execute_task
  File "python/ray/_raylet.pyx", line 463, in ray._raylet.execute_task
  File "python/ray/_raylet.pyx", line 415, in ray._raylet.execute_task.function_executor
  File "/home/davidfan/miniconda3/envs/RL/lib/python3.8/site-packages/ray/rllib/agents/trainer.py", line 499, in train
    self._try_recover()
  File "/home/davidfan/miniconda3/envs/RL/lib/python3.8/site-packages/ray/rllib/agents/trainer.py", line 1117, in _try_recover
    raise RuntimeError(
RuntimeError: Not enough healthy workers remain to continue.

